
FO:aiogram:Bot: HereIAm [@here_i_ambot]
WARNING:aiogram:Updates were skipped successfully.
INFO:aiogram.dispatcher.dispatcher:Start polling.
INFO:aiogram:Bot: HereIAm [@here_i_ambot]
WARNING:aiogram:Updates were skipped successfully.
INFO:aiogram.dispatcher.dispatcher:Start polling.
ERROR:aiogram.dispatcher.dispatcher:Cause exception while getting updates.
Traceback (most recent call last):
  File "/home/danek/.local/lib/python3.8/site-packages/aiogram/dispatcher/dispatcher.py", line 380, in start_polling
    updates = await self.bot.get_updates(
  File "/home/danek/.local/lib/python3.8/site-packages/aiogram/bot/bot.py", line 97, in get_updates
    result = await self.request(api.Methods.GET_UPDATES, payload)
  File "/home/danek/.local/lib/python3.8/site-packages/aiogram/bot/base.py", line 208, in request
    return await api.make_request(self.session, self.server, self.__token, method, data, files,
  File "/home/danek/.local/lib/python3.8/site-packages/aiogram/bot/api.py", line 140, in make_request
    return check_result(method, response.content_type, response.status, await response.text())
  File "/home/danek/.local/lib/python3.8/site-packages/aiogram/bot/api.py", line 119, in check_result
    exceptions.ConflictError.detect(description)
  File "/home/danek/.local/lib/python3.8/site-packages/aiogram/utils/exceptions.py", line 140, in detect
    raise err(cls.text or description)
aiogram.utils.exceptions.TerminatedByOtherGetUpdates: Terminated by other getupdates request; make sure that only one bot instance is running
INFO:root:Cancelling state Form:feedback
ERROR:asyncio:Task exception was never retrieved
future: <Task finished name='Task-15' coro=<Dispatcher._process_polling_updates() done, defined at /home/danek/.local/lib/python3.8/site-packages/aiogram/dispatcher/dispatcher.py:406> exception=TypeError('cancel() takes 0 positional arguments but 1 was given')>
Traceback (most recent call last):
  File "/home/danek/.local/lib/python3.8/site-packages/aiogram/dispatcher/dispatcher.py", line 414, in _process_polling_updates
    for responses in itertools.chain.from_iterable(await self.process_updates(updates, fast)):
  File "/home/danek/.local/lib/python3.8/site-packages/aiogram/dispatcher/dispatcher.py", line 236, in process_updates
    return await asyncio.gather(*tasks)
  File "/home/danek/.local/lib/python3.8/site-packages/aiogram/dispatcher/handler.py", line 116, in notify
    response = await handler_obj.handler(*args, **partial_data)
  File "/home/danek/.local/lib/python3.8/site-packages/aiogram/dispatcher/dispatcher.py", line 257, in process_update
    return await self.message_handlers.notify(update.message)
  File "/home/danek/.local/lib/python3.8/site-packages/aiogram/dispatcher/handler.py", line 116, in notify
    response = await handler_obj.handler(*args, **partial_data)
  File "/home/danek/here-i-ambot/handlers.py", line 65, in cancel_handler
    await cancel(message.from_user.id)
TypeError: cancel() takes 0 positional arguments but 1 was given
ERROR:aiogram.dispatcher.dispatcher:Cause exception while getting updates.
Traceback (most recent call last):
  File "/home/danek/.local/lib/python3.8/site-packages/aiogram/dispatcher/dispatcher.py", line 380, in start_polling
    updates = await self.bot.get_updates(
  File "/home/danek/.local/lib/python3.8/site-packages/aiogram/bot/bot.py", line 97, in get_updates
    result = await self.request(api.Methods.GET_UPDATES, payload)
  File "/home/danek/.local/lib/python3.8/site-packages/aiogram/bot/base.py", line 208, in request
    return await api.make_request(self.session, self.server, self.__token, method, data, files,
  File "/home/danek/.local/lib/python3.8/site-packages/aiogram/bot/api.py", line 140, in make_request
    return check_result(method, response.content_type, response.status, await response.text())
  File "/home/danek/.local/lib/python3.8/site-packages/aiogram/bot/api.py", line 119, in check_result
    exceptions.ConflictError.detect(description)
  File "/home/danek/.local/lib/python3.8/site-packages/aiogram/utils/exceptions.py", line 140, in detect
    raise err(cls.text or description)
aiogram.utils.exceptions.TerminatedByOtherGetUpdates: Terminated by other getupdates request; make sure that only one bot instance is running
ERROR:aiogram.dispatcher.dispatcher:Cause exception while getting updates.
Traceback (most recent call last):
  File "/home/danek/.local/lib/python3.8/site-packages/aiogram/dispatcher/dispatcher.py", line 380, in start_polling
    updates = await self.bot.get_updates(
  File "/home/danek/.local/lib/python3.8/site-packages/aiogram/bot/bot.py", line 97, in get_updates
    result = await self.request(api.Methods.GET_UPDATES, payload)
  File "/home/danek/.local/lib/python3.8/site-packages/aiogram/bot/base.py", line 208, in request
    return await api.make_request(self.session, self.server, self.__token, method, data, files,
  File "/home/danek/.local/lib/python3.8/site-packages/aiogram/bot/api.py", line 140, in make_request
    return check_result(method, response.content_type, response.status, await response.text())
  File "/home/danek/.local/lib/python3.8/site-packages/aiogram/bot/api.py", line 119, in check_result
    exceptions.ConflictError.detect(description)
  File "/home/danek/.local/lib/python3.8/site-packages/aiogram/utils/exceptions.py", line 140, in detect
    raise err(cls.text or description)
aiogram.utils.exceptions.TerminatedByOtherGetUpdates: Terminated by other getupdates request; make sure that only one bot instance is running
ERROR:aiogram.dispatcher.dispatcher:Cause exception while getting updates.
Traceback (most recent call last):
  File "/home/danek/.local/lib/python3.8/site-packages/aiogram/dispatcher/dispatcher.py", line 380, in start_polling
    updates = await self.bot.get_updates(
  File "/home/danek/.local/lib/python3.8/site-packages/aiogram/bot/bot.py", line 97, in get_updates
    result = await self.request(api.Methods.GET_UPDATES, payload)
  File "/home/danek/.local/lib/python3.8/site-packages/aiogram/bot/base.py", line 208, in request
    return await api.make_request(self.session, self.server, self.__token, method, data, files,
  File "/home/danek/.local/lib/python3.8/site-packages/aiogram/bot/api.py", line 140, in make_request
    return check_result(method, response.content_type, response.status, await response.text())
  File "/home/danek/.local/lib/python3.8/site-packages/aiogram/bot/api.py", line 119, in check_result
    exceptions.ConflictError.detect(description)
  File "/home/danek/.local/lib/python3.8/site-packages/aiogram/utils/exceptions.py", line 140, in detect
    raise err(cls.text or description)
aiogram.utils.exceptions.TerminatedByOtherGetUpdates: Terminated by other getupdates request; make sure that only one bot instance is running
ERROR:aiogram.dispatcher.dispatcher:Cause exception while getting updates.
Traceback (most recent call last):
  File "/home/danek/.local/lib/python3.8/site-packages/aiogram/dispatcher/dispatcher.py", line 380, in start_polling
    updates = await self.bot.get_updates(
  File "/home/danek/.local/lib/python3.8/site-packages/aiogram/bot/bot.py", line 97, in get_updates
    result = await self.request(api.Methods.GET_UPDATES, payload)
  File "/home/danek/.local/lib/python3.8/site-packages/aiogram/bot/base.py", line 208, in request
    return await api.make_request(self.session, self.server, self.__token, method, data, files,
  File "/home/danek/.local/lib/python3.8/site-packages/aiogram/bot/api.py", line 140, in make_request
    return check_result(method, response.content_type, response.status, await response.text())
  File "/home/danek/.local/lib/python3.8/site-packages/aiogram/bot/api.py", line 119, in check_result
    exceptions.ConflictError.detect(description)
  File "/home/danek/.local/lib/python3.8/site-packages/aiogram/utils/exceptions.py", line 140, in detect
    raise err(cls.text or description)
aiogram.utils.exceptions.TerminatedByOtherGetUpdates: Terminated by other getupdates request; make sure that only one bot instance is running
