INFO:aiogram.dispatcher.dispatcher:Stop polling...
WARNING:aiogram:Goodbye!
INFO:aiogram:Bot: FINDME [@find_me_test_bot]
WARNING:aiogram:Updates were skipped successfully.
INFO:aiogram.dispatcher.dispatcher:Start polling.
INFO:aiogram.dispatcher.dispatcher:Stop polling...
WARNING:aiogram:Goodbye!
INFO:aiogram:Bot: FINDME [@find_me_test_bot]
WARNING:aiogram:Updates were skipped successfully.
INFO:aiogram.dispatcher.dispatcher:Start polling.
ERROR:asyncio:Task exception was never retrieved
future: <Task finished name='Task-23' coro=<Dispatcher._process_polling_updates() done, defined at C:\Users\danys\PycharmProjects\here_i_ambot\venv\lib\site-packages\aiogram\dispatcher\dispatcher.py:406> exception=TypeError("'NoneType' object is not subscriptable")>
Traceback (most recent call last):
  File "C:\Users\danys\PycharmProjects\here_i_ambot\venv\lib\site-packages\aiogram\dispatcher\dispatcher.py", line 414, in _process_polling_updates
    for responses in itertools.chain.from_iterable(await self.process_updates(updates, fast)):
  File "C:\Users\danys\PycharmProjects\here_i_ambot\venv\lib\site-packages\aiogram\dispatcher\dispatcher.py", line 236, in process_updates
    return await asyncio.gather(*tasks)
  File "C:\Users\danys\PycharmProjects\here_i_ambot\venv\lib\site-packages\aiogram\dispatcher\handler.py", line 116, in notify
    response = await handler_obj.handler(*args, **partial_data)
  File "C:\Users\danys\PycharmProjects\here_i_ambot\venv\lib\site-packages\aiogram\dispatcher\dispatcher.py", line 257, in process_update
    return await self.message_handlers.notify(update.message)
  File "C:\Users\danys\PycharmProjects\here_i_ambot\venv\lib\site-packages\aiogram\dispatcher\handler.py", line 116, in notify
    response = await handler_obj.handler(*args, **partial_data)
  File "C:\Users\danys\PycharmProjects\here-i-ambot\handlers.py", line 106, in find_person
    if str(message.contact['phone_number']).startswith("+"):
TypeError: 'NoneType' object is not subscriptable
INFO:aiogram.dispatcher.dispatcher:Stop polling...
WARNING:aiogram:Goodbye!
INFO:aiogram:Bot: FINDME [@find_me_test_bot]
WARNING:aiogram:Updates were skipped successfully.
INFO:aiogram.dispatcher.dispatcher:Start polling.
INFO:aiogram.dispatcher.dispatcher:Stop polling...
WARNING:aiogram:Goodbye!
INFO:aiogram:Bot: FINDME [@find_me_test_bot]
WARNING:aiogram:Updates were skipped successfully.
INFO:aiogram.dispatcher.dispatcher:Start polling.
ERROR:asyncio:Task exception was never retrieved
future: <Task finished name='Task-14' coro=<Dispatcher._process_polling_updates() done, defined at C:\Users\danys\PycharmProjects\here_i_ambot\venv\lib\site-packages\aiogram\dispatcher\dispatcher.py:406> exception=IndexError('list index out of range')>
Traceback (most recent call last):
  File "C:\Users\danys\PycharmProjects\here_i_ambot\venv\lib\site-packages\aiogram\dispatcher\dispatcher.py", line 414, in _process_polling_updates
    for responses in itertools.chain.from_iterable(await self.process_updates(updates, fast)):
  File "C:\Users\danys\PycharmProjects\here_i_ambot\venv\lib\site-packages\aiogram\dispatcher\dispatcher.py", line 236, in process_updates
    return await asyncio.gather(*tasks)
  File "C:\Users\danys\PycharmProjects\here_i_ambot\venv\lib\site-packages\aiogram\dispatcher\handler.py", line 116, in notify
    response = await handler_obj.handler(*args, **partial_data)
  File "C:\Users\danys\PycharmProjects\here_i_ambot\venv\lib\site-packages\aiogram\dispatcher\dispatcher.py", line 257, in process_update
    return await self.message_handlers.notify(update.message)
  File "C:\Users\danys\PycharmProjects\here_i_ambot\venv\lib\site-packages\aiogram\dispatcher\handler.py", line 116, in notify
    response = await handler_obj.handler(*args, **partial_data)
  File "C:\Users\danys\PycharmProjects\here-i-ambot\handlers.py", line 160, in give_contact
    await bot.send_message(chat_id=queries[message.from_user.id][-1],
IndexError: list index out of range
INFO:aiogram.dispatcher.dispatcher:Stop polling...
WARNING:aiogram:Goodbye!
INFO:aiogram:Bot: FINDME [@find_me_test_bot]
WARNING:aiogram:Updates were skipped successfully.
INFO:aiogram.dispatcher.dispatcher:Start polling.
INFO:aiogram.dispatcher.dispatcher:Stop polling...
WARNING:aiogram:Goodbye!
INFO:aiogram:Bot: FINDME [@find_me_test_bot]
WARNING:aiogram:Updates were skipped successfully.
INFO:aiogram.dispatcher.dispatcher:Start polling.
INFO:aiogram.dispatcher.dispatcher:Stop polling...
WARNING:aiogram:Goodbye!
INFO:aiogram:Bot: FINDME [@find_me_test_bot]
WARNING:aiogram:Updates were skipped successfully.
INFO:aiogram.dispatcher.dispatcher:Start polling.
INFO:aiogram.dispatcher.dispatcher:Stop polling...
WARNING:aiogram:Goodbye!
INFO:aiogram:Bot: FINDME [@find_me_test_bot]
WARNING:aiogram:Updates were skipped successfully.
INFO:aiogram.dispatcher.dispatcher:Start polling.
ERROR:asyncio:Task exception was never retrieved
future: <Task finished name='Task-36' coro=<Dispatcher._process_polling_updates() done, defined at C:\Users\danys\PycharmProjects\here_i_ambot\venv\lib\site-packages\aiogram\dispatcher\dispatcher.py:406> exception=TypeError("give_contact() missing 2 required positional arguments: 'message' and 'state'")>
Traceback (most recent call last):
  File "C:\Users\danys\PycharmProjects\here_i_ambot\venv\lib\site-packages\aiogram\dispatcher\dispatcher.py", line 414, in _process_polling_updates
    for responses in itertools.chain.from_iterable(await self.process_updates(updates, fast)):
  File "C:\Users\danys\PycharmProjects\here_i_ambot\venv\lib\site-packages\aiogram\dispatcher\dispatcher.py", line 236, in process_updates
    return await asyncio.gather(*tasks)
  File "C:\Users\danys\PycharmProjects\here_i_ambot\venv\lib\site-packages\aiogram\dispatcher\handler.py", line 116, in notify
    response = await handler_obj.handler(*args, **partial_data)
  File "C:\Users\danys\PycharmProjects\here_i_ambot\venv\lib\site-packages\aiogram\dispatcher\dispatcher.py", line 257, in process_update
    return await self.message_handlers.notify(update.message)
  File "C:\Users\danys\PycharmProjects\here_i_ambot\venv\lib\site-packages\aiogram\dispatcher\handler.py", line 116, in notify
    response = await handler_obj.handler(*args, **partial_data)
  File "C:\Users\danys\PycharmProjects\here-i-ambot\handlers.py", line 102, in find_person
    await give_contact()  # ������� �������
TypeError: give_contact() missing 2 required positional arguments: 'message' and 'state'
INFO:aiogram.dispatcher.dispatcher:Stop polling...
WARNING:aiogram:Goodbye!
INFO:aiogram:Bot: FINDME [@find_me_test_bot]
WARNING:aiogram:Updates were skipped successfully.
INFO:aiogram.dispatcher.dispatcher:Start polling.
ERROR:asyncio:Task exception was never retrieved
future: <Task finished name='Task-23' coro=<Dispatcher._process_polling_updates() done, defined at C:\Users\danys\PycharmProjects\here_i_ambot\venv\lib\site-packages\aiogram\dispatcher\dispatcher.py:406> exception=AttributeError("'NoneType' object has no attribute 'values'")>
Traceback (most recent call last):
  File "C:\Users\danys\PycharmProjects\here_i_ambot\venv\lib\site-packages\aiogram\dispatcher\dispatcher.py", line 414, in _process_polling_updates
    for responses in itertools.chain.from_iterable(await self.process_updates(updates, fast)):
  File "C:\Users\danys\PycharmProjects\here_i_ambot\venv\lib\site-packages\aiogram\dispatcher\dispatcher.py", line 236, in process_updates
    return await asyncio.gather(*tasks)
  File "C:\Users\danys\PycharmProjects\here_i_ambot\venv\lib\site-packages\aiogram\dispatcher\handler.py", line 116, in notify
    response = await handler_obj.handler(*args, **partial_data)
  File "C:\Users\danys\PycharmProjects\here_i_ambot\venv\lib\site-packages\aiogram\dispatcher\dispatcher.py", line 257, in process_update
    return await self.message_handlers.notify(update.message)
  File "C:\Users\danys\PycharmProjects\here_i_ambot\venv\lib\site-packages\aiogram\dispatcher\handler.py", line 116, in notify
    response = await handler_obj.handler(*args, **partial_data)
  File "C:\Users\danys\PycharmProjects\here-i-ambot\handlers.py", line 102, in find_person
    await give_contact(message=types.Message, state=FSMContext)  # ������� �������
  File "C:\Users\danys\PycharmProjects\here-i-ambot\handlers.py", line 162, in give_contact
    await bot.send_message(chat_id=queries[message.from_user.id][-1],
  File "C:\Users\danys\PycharmProjects\here_i_ambot\venv\lib\site-packages\aiogram\types\fields.py", line 68, in __get__
    return self.get_value(instance)
  File "C:\Users\danys\PycharmProjects\here_i_ambot\venv\lib\site-packages\aiogram\types\fields.py", line 45, in get_value
    return instance.values.get(self.alias, self.default)
AttributeError: 'NoneType' object has no attribute 'values'
INFO:aiogram.dispatcher.dispatcher:Stop polling...
WARNING:aiogram:Goodbye!
INFO:aiogram:Bot: FINDME [@find_me_test_bot]
WARNING:aiogram:Updates were skipped successfully.
INFO:aiogram.dispatcher.dispatcher:Start polling.
INFO:aiogram.dispatcher.dispatcher:Stop polling...
WARNING:aiogram:Goodbye!
INFO:aiogram:Bot: FINDME [@find_me_test_bot]
WARNING:aiogram:Updates were skipped successfully.
INFO:aiogram.dispatcher.dispatcher:Start polling.
INFO:aiogram.dispatcher.dispatcher:Stop polling...
WARNING:aiogram:Goodbye!
INFO:aiogram:Bot: FINDME [@find_me_test_bot]
WARNING:aiogram:Updates were skipped successfully.
INFO:aiogram.dispatcher.dispatcher:Start polling.
ERROR:asyncio:Task exception was never retrieved
future: <Task finished name='Task-130' coro=<Dispatcher._process_polling_updates() done, defined at C:\Users\danys\PycharmProjects\here_i_ambot\venv\lib\site-packages\aiogram\dispatcher\dispatcher.py:406> exception=IndexError('list index out of range')>
Traceback (most recent call last):
  File "C:\Users\danys\PycharmProjects\here_i_ambot\venv\lib\site-packages\aiogram\dispatcher\dispatcher.py", line 414, in _process_polling_updates
    for responses in itertools.chain.from_iterable(await self.process_updates(updates, fast)):
  File "C:\Users\danys\PycharmProjects\here_i_ambot\venv\lib\site-packages\aiogram\dispatcher\dispatcher.py", line 236, in process_updates
    return await asyncio.gather(*tasks)
  File "C:\Users\danys\PycharmProjects\here_i_ambot\venv\lib\site-packages\aiogram\dispatcher\handler.py", line 116, in notify
    response = await handler_obj.handler(*args, **partial_data)
  File "C:\Users\danys\PycharmProjects\here_i_ambot\venv\lib\site-packages\aiogram\dispatcher\dispatcher.py", line 257, in process_update
    return await self.message_handlers.notify(update.message)
  File "C:\Users\danys\PycharmProjects\here_i_ambot\venv\lib\site-packages\aiogram\dispatcher\handler.py", line 116, in notify
    response = await handler_obj.handler(*args, **partial_data)
  File "C:\Users\danys\PycharmProjects\here-i-ambot\handlers.py", line 164, in give_contact
    await bot.send_message(chat_id=queries[message.from_user.id][-1],
IndexError: list index out of range
ERROR:asyncio:Task exception was never retrieved
future: <Task finished name='Task-137' coro=<Dispatcher._process_polling_updates() done, defined at C:\Users\danys\PycharmProjects\here_i_ambot\venv\lib\site-packages\aiogram\dispatcher\dispatcher.py:406> exception=IndexError('list index out of range')>
Traceback (most recent call last):
  File "C:\Users\danys\PycharmProjects\here_i_ambot\venv\lib\site-packages\aiogram\dispatcher\dispatcher.py", line 414, in _process_polling_updates
    for responses in itertools.chain.from_iterable(await self.process_updates(updates, fast)):
  File "C:\Users\danys\PycharmProjects\here_i_ambot\venv\lib\site-packages\aiogram\dispatcher\dispatcher.py", line 236, in process_updates
    return await asyncio.gather(*tasks)
  File "C:\Users\danys\PycharmProjects\here_i_ambot\venv\lib\site-packages\aiogram\dispatcher\handler.py", line 116, in notify
    response = await handler_obj.handler(*args, **partial_data)
  File "C:\Users\danys\PycharmProjects\here_i_ambot\venv\lib\site-packages\aiogram\dispatcher\dispatcher.py", line 257, in process_update
    return await self.message_handlers.notify(update.message)
  File "C:\Users\danys\PycharmProjects\here_i_ambot\venv\lib\site-packages\aiogram\dispatcher\handler.py", line 116, in notify
    response = await handler_obj.handler(*args, **partial_data)
  File "C:\Users\danys\PycharmProjects\here-i-ambot\handlers.py", line 164, in give_contact
    await bot.send_message(chat_id=queries[message.from_user.id][-1],
IndexError: list index out of range
ERROR:asyncio:Task exception was never retrieved
future: <Task finished name='Task-146' coro=<Dispatcher._process_polling_updates() done, defined at C:\Users\danys\PycharmProjects\here_i_ambot\venv\lib\site-packages\aiogram\dispatcher\dispatcher.py:406> exception=IndexError('list index out of range')>
Traceback (most recent call last):
  File "C:\Users\danys\PycharmProjects\here_i_ambot\venv\lib\site-packages\aiogram\dispatcher\dispatcher.py", line 414, in _process_polling_updates
    for responses in itertools.chain.from_iterable(await self.process_updates(updates, fast)):
  File "C:\Users\danys\PycharmProjects\here_i_ambot\venv\lib\site-packages\aiogram\dispatcher\dispatcher.py", line 236, in process_updates
    return await asyncio.gather(*tasks)
  File "C:\Users\danys\PycharmProjects\here_i_ambot\venv\lib\site-packages\aiogram\dispatcher\handler.py", line 116, in notify
    response = await handler_obj.handler(*args, **partial_data)
  File "C:\Users\danys\PycharmProjects\here_i_ambot\venv\lib\site-packages\aiogram\dispatcher\dispatcher.py", line 257, in process_update
    return await self.message_handlers.notify(update.message)
  File "C:\Users\danys\PycharmProjects\here_i_ambot\venv\lib\site-packages\aiogram\dispatcher\handler.py", line 116, in notify
    response = await handler_obj.handler(*args, **partial_data)
  File "C:\Users\danys\PycharmProjects\here-i-ambot\handlers.py", line 164, in give_contact
    await bot.send_message(chat_id=queries[message.from_user.id][-1],
IndexError: list index out of range
INFO:aiogram.dispatcher.dispatcher:Stop polling...
WARNING:aiogram:Goodbye!
INFO:aiogram:Bot: FINDME [@find_me_test_bot]
WARNING:aiogram:Updates were skipped successfully.
INFO:aiogram.dispatcher.dispatcher:Start polling.
INFO:aiogram.dispatcher.dispatcher:Stop polling...
WARNING:aiogram:Goodbye!
INFO:aiogram:Bot: FINDME [@find_me_test_bot]
WARNING:aiogram:Updates were skipped successfully.
INFO:aiogram.dispatcher.dispatcher:Start polling.
ERROR:asyncio:Task exception was never retrieved
future: <Task finished name='Task-31' coro=<Dispatcher._process_polling_updates() done, defined at C:\Users\danys\PycharmProjects\here_i_ambot\venv\lib\site-packages\aiogram\dispatcher\dispatcher.py:406> exception=IndexError('list index out of range')>
Traceback (most recent call last):
  File "C:\Users\danys\PycharmProjects\here_i_ambot\venv\lib\site-packages\aiogram\dispatcher\dispatcher.py", line 414, in _process_polling_updates
    for responses in itertools.chain.from_iterable(await self.process_updates(updates, fast)):
  File "C:\Users\danys\PycharmProjects\here_i_ambot\venv\lib\site-packages\aiogram\dispatcher\dispatcher.py", line 236, in process_updates
    return await asyncio.gather(*tasks)
  File "C:\Users\danys\PycharmProjects\here_i_ambot\venv\lib\site-packages\aiogram\dispatcher\handler.py", line 116, in notify
    response = await handler_obj.handler(*args, **partial_data)
  File "C:\Users\danys\PycharmProjects\here_i_ambot\venv\lib\site-packages\aiogram\dispatcher\dispatcher.py", line 257, in process_update
    return await self.message_handlers.notify(update.message)
  File "C:\Users\danys\PycharmProjects\here_i_ambot\venv\lib\site-packages\aiogram\dispatcher\handler.py", line 116, in notify
    response = await handler_obj.handler(*args, **partial_data)
  File "C:\Users\danys\PycharmProjects\here-i-ambot\handlers.py", line 166, in give_contact
    await bot.send_message(chat_id=queries[message.from_user.id][-1],
IndexError: list index out of range
INFO:aiogram.dispatcher.dispatcher:Stop polling...
WARNING:aiogram:Goodbye!
INFO:aiogram:Bot: FINDME [@find_me_test_bot]
WARNING:aiogram:Updates were skipped successfully.
INFO:aiogram.dispatcher.dispatcher:Start polling.
ERROR:asyncio:Task exception was never retrieved
future: <Task finished name='Task-18' coro=<Dispatcher._process_polling_updates() done, defined at C:\Users\danys\PycharmProjects\here_i_ambot\venv\lib\site-packages\aiogram\dispatcher\dispatcher.py:406> exception=IndexError('list index out of range')>
Traceback (most recent call last):
  File "C:\Users\danys\PycharmProjects\here_i_ambot\venv\lib\site-packages\aiogram\dispatcher\dispatcher.py", line 414, in _process_polling_updates
    for responses in itertools.chain.from_iterable(await self.process_updates(updates, fast)):
  File "C:\Users\danys\PycharmProjects\here_i_ambot\venv\lib\site-packages\aiogram\dispatcher\dispatcher.py", line 236, in process_updates
    return await asyncio.gather(*tasks)
  File "C:\Users\danys\PycharmProjects\here_i_ambot\venv\lib\site-packages\aiogram\dispatcher\handler.py", line 116, in notify
    response = await handler_obj.handler(*args, **partial_data)
  File "C:\Users\danys\PycharmProjects\here_i_ambot\venv\lib\site-packages\aiogram\dispatcher\dispatcher.py", line 257, in process_update
    return await self.message_handlers.notify(update.message)
  File "C:\Users\danys\PycharmProjects\here_i_ambot\venv\lib\site-packages\aiogram\dispatcher\handler.py", line 116, in notify
    response = await handler_obj.handler(*args, **partial_data)
  File "C:\Users\danys\PycharmProjects\here-i-ambot\handlers.py", line 163, in give_contact
    await bot.send_message(chat_id=queries[message.from_user.id][-1],
IndexError: list index out of range
INFO:aiogram.dispatcher.dispatcher:Stop polling...
WARNING:aiogram:Goodbye!
INFO:aiogram:Bot: FINDME [@find_me_test_bot]
WARNING:aiogram:Updates were skipped successfully.
INFO:aiogram.dispatcher.dispatcher:Start polling.
ERROR:asyncio:Task exception was never retrieved
future: <Task finished name='Task-18' coro=<Dispatcher._process_polling_updates() done, defined at C:\Users\danys\PycharmProjects\here_i_ambot\venv\lib\site-packages\aiogram\dispatcher\dispatcher.py:406> exception=IndexError('list index out of range')>
Traceback (most recent call last):
  File "C:\Users\danys\PycharmProjects\here_i_ambot\venv\lib\site-packages\aiogram\dispatcher\dispatcher.py", line 414, in _process_polling_updates
    for responses in itertools.chain.from_iterable(await self.process_updates(updates, fast)):
  File "C:\Users\danys\PycharmProjects\here_i_ambot\venv\lib\site-packages\aiogram\dispatcher\dispatcher.py", line 236, in process_updates
    return await asyncio.gather(*tasks)
  File "C:\Users\danys\PycharmProjects\here_i_ambot\venv\lib\site-packages\aiogram\dispatcher\handler.py", line 116, in notify
    response = await handler_obj.handler(*args, **partial_data)
  File "C:\Users\danys\PycharmProjects\here_i_ambot\venv\lib\site-packages\aiogram\dispatcher\dispatcher.py", line 257, in process_update
    return await self.message_handlers.notify(update.message)
  File "C:\Users\danys\PycharmProjects\here_i_ambot\venv\lib\site-packages\aiogram\dispatcher\handler.py", line 116, in notify
    response = await handler_obj.handler(*args, **partial_data)
  File "C:\Users\danys\PycharmProjects\here-i-ambot\handlers.py", line 164, in give_contact
    await bot.send_message(chat_id=queries[message.from_user.id][-1],
IndexError: list index out of range
INFO:aiogram.dispatcher.dispatcher:Stop polling...
WARNING:aiogram:Goodbye!
INFO:aiogram:Bot: FINDME [@find_me_test_bot]
WARNING:aiogram:Updates were skipped successfully.
INFO:aiogram.dispatcher.dispatcher:Start polling.
INFO:aiogram.dispatcher.dispatcher:Stop polling...
WARNING:aiogram:Goodbye!
INFO:aiogram:Bot: FINDME [@find_me_test_bot]
WARNING:aiogram:Updates were skipped successfully.
INFO:aiogram.dispatcher.dispatcher:Start polling.
ERROR:asyncio:Task exception was never retrieved
future: <Task finished name='Task-19' coro=<Dispatcher._process_polling_updates() done, defined at C:\Users\danys\PycharmProjects\here_i_ambot\venv\lib\site-packages\aiogram\dispatcher\dispatcher.py:406> exception=IndexError('list index out of range')>
Traceback (most recent call last):
  File "C:\Users\danys\PycharmProjects\here_i_ambot\venv\lib\site-packages\aiogram\dispatcher\dispatcher.py", line 414, in _process_polling_updates
    for responses in itertools.chain.from_iterable(await self.process_updates(updates, fast)):
  File "C:\Users\danys\PycharmProjects\here_i_ambot\venv\lib\site-packages\aiogram\dispatcher\dispatcher.py", line 236, in process_updates
    return await asyncio.gather(*tasks)
  File "C:\Users\danys\PycharmProjects\here_i_ambot\venv\lib\site-packages\aiogram\dispatcher\handler.py", line 116, in notify
    response = await handler_obj.handler(*args, **partial_data)
  File "C:\Users\danys\PycharmProjects\here_i_ambot\venv\lib\site-packages\aiogram\dispatcher\dispatcher.py", line 257, in process_update
    return await self.message_handlers.notify(update.message)
  File "C:\Users\danys\PycharmProjects\here_i_ambot\venv\lib\site-packages\aiogram\dispatcher\handler.py", line 116, in notify
    response = await handler_obj.handler(*args, **partial_data)
  File "C:\Users\danys\PycharmProjects\here-i-ambot\handlers.py", line 166, in give_contact
    await bot.send_message(chat_id=queries[message.from_user.id][-1],
IndexError: list index out of range
INFO:aiogram.dispatcher.dispatcher:Stop polling...
WARNING:aiogram:Goodbye!
INFO:aiogram:Bot: FINDME [@find_me_test_bot]
WARNING:aiogram:Updates were skipped successfully.
INFO:aiogram.dispatcher.dispatcher:Start polling.
INFO:aiogram.dispatcher.dispatcher:Stop polling...
WARNING:aiogram:Goodbye!
INFO:aiogram:Bot: HereIAm [@here_i_ambot]
WARNING:aiogram:Updates were skipped successfully.
INFO:aiogram.dispatcher.dispatcher:Start polling.
ERROR:aiogram.dispatcher.dispatcher:Cause exception while getting updates.
Traceback (most recent call last):
  File "/home/danek/.local/lib/python3.8/site-packages/aiogram/dispatcher/dispatcher.py", line 380, in start_polling
    updates = await self.bot.get_updates(
  File "/home/danek/.local/lib/python3.8/site-packages/aiogram/bot/bot.py", line 97, in get_updates
    result = await self.request(api.Methods.GET_UPDATES, payload)
  File "/home/danek/.local/lib/python3.8/site-packages/aiogram/bot/base.py", line 208, in request
    return await api.make_request(self.session, self.server, self.__token, method, data, files,
  File "/home/danek/.local/lib/python3.8/site-packages/aiogram/bot/api.py", line 140, in make_request
    return check_result(method, response.content_type, response.status, await response.text())
  File "/home/danek/.local/lib/python3.8/site-packages/aiogram/bot/api.py", line 119, in check_result
    exceptions.ConflictError.detect(description)
  File "/home/danek/.local/lib/python3.8/site-packages/aiogram/utils/exceptions.py", line 140, in detect
    raise err(cls.text or description)
aiogram.utils.exceptions.TerminatedByOtherGetUpdates: Terminated by other getupdates request; make sure that only one bot instance is running
INFO:root:Cancelling state Form:feedback
ERROR:asyncio:Task exception was never retrieved
future: <Task finished name='Task-15' coro=<Dispatcher._process_polling_updates() done, defined at /home/danek/.local/lib/python3.8/site-packages/aiogram/dispatcher/dispatcher.py:406> exception=TypeError('cancel() takes 0 positional arguments but 1 was given')>
Traceback (most recent call last):
  File "/home/danek/.local/lib/python3.8/site-packages/aiogram/dispatcher/dispatcher.py", line 414, in _process_polling_updates
    for responses in itertools.chain.from_iterable(await self.process_updates(updates, fast)):
  File "/home/danek/.local/lib/python3.8/site-packages/aiogram/dispatcher/dispatcher.py", line 236, in process_updates
    return await asyncio.gather(*tasks)
  File "/home/danek/.local/lib/python3.8/site-packages/aiogram/dispatcher/handler.py", line 116, in notify
    response = await handler_obj.handler(*args, **partial_data)
  File "/home/danek/.local/lib/python3.8/site-packages/aiogram/dispatcher/dispatcher.py", line 257, in process_update
    return await self.message_handlers.notify(update.message)
  File "/home/danek/.local/lib/python3.8/site-packages/aiogram/dispatcher/handler.py", line 116, in notify
    response = await handler_obj.handler(*args, **partial_data)
  File "/home/danek/here-i-ambot/handlers.py", line 65, in cancel_handler
    await cancel(message.from_user.id)
TypeError: cancel() takes 0 positional arguments but 1 was given
ERROR:aiogram.dispatcher.dispatcher:Cause exception while getting updates.
Traceback (most recent call last):
  File "/home/danek/.local/lib/python3.8/site-packages/aiogram/dispatcher/dispatcher.py", line 380, in start_polling
    updates = await self.bot.get_updates(
  File "/home/danek/.local/lib/python3.8/site-packages/aiogram/bot/bot.py", line 97, in get_updates
    result = await self.request(api.Methods.GET_UPDATES, payload)
  File "/home/danek/.local/lib/python3.8/site-packages/aiogram/bot/base.py", line 208, in request
    return await api.make_request(self.session, self.server, self.__token, method, data, files,
  File "/home/danek/.local/lib/python3.8/site-packages/aiogram/bot/api.py", line 140, in make_request
    return check_result(method, response.content_type, response.status, await response.text())
  File "/home/danek/.local/lib/python3.8/site-packages/aiogram/bot/api.py", line 119, in check_result
    exceptions.ConflictError.detect(description)
  File "/home/danek/.local/lib/python3.8/site-packages/aiogram/utils/exceptions.py", line 140, in detect
    raise err(cls.text or description)
aiogram.utils.exceptions.TerminatedByOtherGetUpdates: Terminated by other getupdates request; make sure that only one bot instance is running
ERROR:aiogram.dispatcher.dispatcher:Cause exception while getting updates.
Traceback (most recent call last):
  File "/home/danek/.local/lib/python3.8/site-packages/aiogram/dispatcher/dispatcher.py", line 380, in start_polling
    updates = await self.bot.get_updates(
  File "/home/danek/.local/lib/python3.8/site-packages/aiogram/bot/bot.py", line 97, in get_updates
    result = await self.request(api.Methods.GET_UPDATES, payload)
  File "/home/danek/.local/lib/python3.8/site-packages/aiogram/bot/base.py", line 208, in request
    return await api.make_request(self.session, self.server, self.__token, method, data, files,
  File "/home/danek/.local/lib/python3.8/site-packages/aiogram/bot/api.py", line 140, in make_request
    return check_result(method, response.content_type, response.status, await response.text())
  File "/home/danek/.local/lib/python3.8/site-packages/aiogram/bot/api.py", line 119, in check_result
    exceptions.ConflictError.detect(description)
  File "/home/danek/.local/lib/python3.8/site-packages/aiogram/utils/exceptions.py", line 140, in detect
    raise err(cls.text or description)
aiogram.utils.exceptions.TerminatedByOtherGetUpdates: Terminated by other getupdates request; make sure that only one bot instance is running
ERROR:aiogram.dispatcher.dispatcher:Cause exception while getting updates.
Traceback (most recent call last):
  File "/home/danek/.local/lib/python3.8/site-packages/aiogram/dispatcher/dispatcher.py", line 380, in start_polling
    updates = await self.bot.get_updates(
  File "/home/danek/.local/lib/python3.8/site-packages/aiogram/bot/bot.py", line 97, in get_updates
    result = await self.request(api.Methods.GET_UPDATES, payload)
  File "/home/danek/.local/lib/python3.8/site-packages/aiogram/bot/base.py", line 208, in request
    return await api.make_request(self.session, self.server, self.__token, method, data, files,
  File "/home/danek/.local/lib/python3.8/site-packages/aiogram/bot/api.py", line 140, in make_request
    return check_result(method, response.content_type, response.status, await response.text())
  File "/home/danek/.local/lib/python3.8/site-packages/aiogram/bot/api.py", line 119, in check_result
    exceptions.ConflictError.detect(description)
  File "/home/danek/.local/lib/python3.8/site-packages/aiogram/utils/exceptions.py", line 140, in detect
    raise err(cls.text or description)
aiogram.utils.exceptions.TerminatedByOtherGetUpdates: Terminated by other getupdates request; make sure that only one bot instance is running
ERROR:aiogram.dispatcher.dispatcher:Cause exception while getting updates.
Traceback (most recent call last):
  File "/home/danek/.local/lib/python3.8/site-packages/aiogram/dispatcher/dispatcher.py", line 380, in start_polling
    updates = await self.bot.get_updates(
  File "/home/danek/.local/lib/python3.8/site-packages/aiogram/bot/bot.py", line 97, in get_updates
    result = await self.request(api.Methods.GET_UPDATES, payload)
  File "/home/danek/.local/lib/python3.8/site-packages/aiogram/bot/base.py", line 208, in request
    return await api.make_request(self.session, self.server, self.__token, method, data, files,
  File "/home/danek/.local/lib/python3.8/site-packages/aiogram/bot/api.py", line 140, in make_request
    return check_result(method, response.content_type, response.status, await response.text())
  File "/home/danek/.local/lib/python3.8/site-packages/aiogram/bot/api.py", line 119, in check_result
    exceptions.ConflictError.detect(description)
  File "/home/danek/.local/lib/python3.8/site-packages/aiogram/utils/exceptions.py", line 140, in detect
    raise err(cls.text or description)
aiogram.utils.exceptions.TerminatedByOtherGetUpdates: Terminated by other getupdates request; make sure that only one bot instance is running
ERROR:aiogram.dispatcher.dispatcher:Cause exception while getting updates.
Traceback (most recent call last):
  File "/home/danek/.local/lib/python3.8/site-packages/aiogram/dispatcher/dispatcher.py", line 380, in start_polling
    updates = await self.bot.get_updates(
  File "/home/danek/.local/lib/python3.8/site-packages/aiogram/bot/bot.py", line 97, in get_updates
    result = await self.request(api.Methods.GET_UPDATES, payload)
  File "/home/danek/.local/lib/python3.8/site-packages/aiogram/bot/base.py", line 208, in request
    return await api.make_request(self.session, self.server, self.__token, method, data, files,
  File "/home/danek/.local/lib/python3.8/site-packages/aiogram/bot/api.py", line 140, in make_request
    return check_result(method, response.content_type, response.status, await response.text())
  File "/home/danek/.local/lib/python3.8/site-packages/aiogram/bot/api.py", line 119, in check_result
    exceptions.ConflictError.detect(description)
  File "/home/danek/.local/lib/python3.8/site-packages/aiogram/utils/exceptions.py", line 140, in detect
    raise err(cls.text or description)
aiogram.utils.exceptions.TerminatedByOtherGetUpdates: Terminated by other getupdates request; make sure that only one bot instance is running
ERROR:aiogram.dispatcher.dispatcher:Cause exception while getting updates.
Traceback (most recent call last):
  File "/home/danek/.local/lib/python3.8/site-packages/aiogram/dispatcher/dispatcher.py", line 380, in start_polling
    updates = await self.bot.get_updates(
  File "/home/danek/.local/lib/python3.8/site-packages/aiogram/bot/bot.py", line 97, in get_updates
    result = await self.request(api.Methods.GET_UPDATES, payload)
  File "/home/danek/.local/lib/python3.8/site-packages/aiogram/bot/base.py", line 208, in request
    return await api.make_request(self.session, self.server, self.__token, method, data, files,
  File "/home/danek/.local/lib/python3.8/site-packages/aiogram/bot/api.py", line 140, in make_request
    return check_result(method, response.content_type, response.status, await response.text())
  File "/home/danek/.local/lib/python3.8/site-packages/aiogram/bot/api.py", line 119, in check_result
    exceptions.ConflictError.detect(description)
  File "/home/danek/.local/lib/python3.8/site-packages/aiogram/utils/exceptions.py", line 140, in detect
    raise err(cls.text or description)
aiogram.utils.exceptions.TerminatedByOtherGetUpdates: Terminated by other getupdates request; make sure that only one bot instance is running
ERROR:aiogram.dispatcher.dispatcher:Cause exception while getting updates.
Traceback (most recent call last):
  File "/home/danek/.local/lib/python3.8/site-packages/aiogram/dispatcher/dispatcher.py", line 380, in start_polling
    updates = await self.bot.get_updates(
  File "/home/danek/.local/lib/python3.8/site-packages/aiogram/bot/bot.py", line 97, in get_updates
    result = await self.request(api.Methods.GET_UPDATES, payload)
  File "/home/danek/.local/lib/python3.8/site-packages/aiogram/bot/base.py", line 208, in request
    return await api.make_request(self.session, self.server, self.__token, method, data, files,
  File "/home/danek/.local/lib/python3.8/site-packages/aiogram/bot/api.py", line 140, in make_request
    return check_result(method, response.content_type, response.status, await response.text())
  File "/home/danek/.local/lib/python3.8/site-packages/aiogram/bot/api.py", line 119, in check_result
    exceptions.ConflictError.detect(description)
  File "/home/danek/.local/lib/python3.8/site-packages/aiogram/utils/exceptions.py", line 140, in detect
    raise err(cls.text or description)
aiogram.utils.exceptions.TerminatedByOtherGetUpdates: Terminated by other getupdates request; make sure that only one bot instance is running
ERROR:aiogram.dispatcher.dispatcher:Cause exception while getting updates.
Traceback (most recent call last):
  File "/home/danek/.local/lib/python3.8/site-packages/aiogram/dispatcher/dispatcher.py", line 380, in start_polling
    updates = await self.bot.get_updates(
  File "/home/danek/.local/lib/python3.8/site-packages/aiogram/bot/bot.py", line 97, in get_updates
    result = await self.request(api.Methods.GET_UPDATES, payload)
  File "/home/danek/.local/lib/python3.8/site-packages/aiogram/bot/base.py", line 208, in request
    return await api.make_request(self.session, self.server, self.__token, method, data, files,
  File "/home/danek/.local/lib/python3.8/site-packages/aiogram/bot/api.py", line 140, in make_request
    return check_result(method, response.content_type, response.status, await response.text())
  File "/home/danek/.local/lib/python3.8/site-packages/aiogram/bot/api.py", line 119, in check_result
    exceptions.ConflictError.detect(description)
  File "/home/danek/.local/lib/python3.8/site-packages/aiogram/utils/exceptions.py", line 140, in detect
    raise err(cls.text or description)
aiogram.utils.exceptions.TerminatedByOtherGetUpdates: Terminated by other getupdates request; make sure that only one bot instance is running
ERROR:aiogram.dispatcher.dispatcher:Cause exception while getting updates.
Traceback (most recent call last):
  File "/home/danek/.local/lib/python3.8/site-packages/aiogram/dispatcher/dispatcher.py", line 380, in start_polling
    updates = await self.bot.get_updates(
  File "/home/danek/.local/lib/python3.8/site-packages/aiogram/bot/bot.py", line 97, in get_updates
    result = await self.request(api.Methods.GET_UPDATES, payload)
  File "/home/danek/.local/lib/python3.8/site-packages/aiogram/bot/base.py", line 208, in request
    return await api.make_request(self.session, self.server, self.__token, method, data, files,
  File "/home/danek/.local/lib/python3.8/site-packages/aiogram/bot/api.py", line 140, in make_request
    return check_result(method, response.content_type, response.status, await response.text())
  File "/home/danek/.local/lib/python3.8/site-packages/aiogram/bot/api.py", line 119, in check_result
    exceptions.ConflictError.detect(description)
  File "/home/danek/.local/lib/python3.8/site-packages/aiogram/utils/exceptions.py", line 140, in detect
    raise err(cls.text or description)
aiogram.utils.exceptions.TerminatedByOtherGetUpdates: Terminated by other getupdates request; make sure that only one bot instance is running
ERROR:aiogram.dispatcher.dispatcher:Cause exception while getting updates.
Traceback (most recent call last):
  File "/home/danek/.local/lib/python3.8/site-packages/aiogram/dispatcher/dispatcher.py", line 380, in start_polling
    updates = await self.bot.get_updates(
  File "/home/danek/.local/lib/python3.8/site-packages/aiogram/bot/bot.py", line 97, in get_updates
    result = await self.request(api.Methods.GET_UPDATES, payload)
  File "/home/danek/.local/lib/python3.8/site-packages/aiogram/bot/base.py", line 208, in request
    return await api.make_request(self.session, self.server, self.__token, method, data, files,
  File "/home/danek/.local/lib/python3.8/site-packages/aiogram/bot/api.py", line 140, in make_request
    return check_result(method, response.content_type, response.status, await response.text())
  File "/home/danek/.local/lib/python3.8/site-packages/aiogram/bot/api.py", line 119, in check_result
    exceptions.ConflictError.detect(description)
  File "/home/danek/.local/lib/python3.8/site-packages/aiogram/utils/exceptions.py", line 140, in detect
    raise err(cls.text or description)
aiogram.utils.exceptions.TerminatedByOtherGetUpdates: Terminated by other getupdates request; make sure that only one bot instance is running
ERROR:aiogram.dispatcher.dispatcher:Cause exception while getting updates.
Traceback (most recent call last):
  File "/home/danek/.local/lib/python3.8/site-packages/aiogram/dispatcher/dispatcher.py", line 380, in start_polling
    updates = await self.bot.get_updates(
  File "/home/danek/.local/lib/python3.8/site-packages/aiogram/bot/bot.py", line 97, in get_updates
    result = await self.request(api.Methods.GET_UPDATES, payload)
  File "/home/danek/.local/lib/python3.8/site-packages/aiogram/bot/base.py", line 208, in request
    return await api.make_request(self.session, self.server, self.__token, method, data, files,
  File "/home/danek/.local/lib/python3.8/site-packages/aiogram/bot/api.py", line 140, in make_request
    return check_result(method, response.content_type, response.status, await response.text())
  File "/home/danek/.local/lib/python3.8/site-packages/aiogram/bot/api.py", line 119, in check_result
    exceptions.ConflictError.detect(description)
  File "/home/danek/.local/lib/python3.8/site-packages/aiogram/utils/exceptions.py", line 140, in detect
    raise err(cls.text or description)
aiogram.utils.exceptions.TerminatedByOtherGetUpdates: Terminated by other getupdates request; make sure that only one bot instance is running
ERROR:aiogram.dispatcher.dispatcher:Cause exception while getting updates.
Traceback (most recent call last):
  File "/home/danek/.local/lib/python3.8/site-packages/aiogram/dispatcher/dispatcher.py", line 380, in start_polling
    updates = await self.bot.get_updates(
  File "/home/danek/.local/lib/python3.8/site-packages/aiogram/bot/bot.py", line 97, in get_updates
    result = await self.request(api.Methods.GET_UPDATES, payload)
  File "/home/danek/.local/lib/python3.8/site-packages/aiogram/bot/base.py", line 208, in request
    return await api.make_request(self.session, self.server, self.__token, method, data, files,
  File "/home/danek/.local/lib/python3.8/site-packages/aiogram/bot/api.py", line 140, in make_request
    return check_result(method, response.content_type, response.status, await response.text())
  File "/home/danek/.local/lib/python3.8/site-packages/aiogram/bot/api.py", line 119, in check_result
    exceptions.ConflictError.detect(description)
  File "/home/danek/.local/lib/python3.8/site-packages/aiogram/utils/exceptions.py", line 140, in detect
    raise err(cls.text or description)
aiogram.utils.exceptions.TerminatedByOtherGetUpdates: Terminated by other getupdates request; make sure that only one bot instance is running
ERROR:aiogram.dispatcher.dispatcher:Cause exception while getting updates.
Traceback (most recent call last):
  File "/home/danek/.local/lib/python3.8/site-packages/aiogram/dispatcher/dispatcher.py", line 380, in start_polling
    updates = await self.bot.get_updates(
  File "/home/danek/.local/lib/python3.8/site-packages/aiogram/bot/bot.py", line 97, in get_updates
    result = await self.request(api.Methods.GET_UPDATES, payload)
  File "/home/danek/.local/lib/python3.8/site-packages/aiogram/bot/base.py", line 208, in request
    return await api.make_request(self.session, self.server, self.__token, method, data, files,
  File "/home/danek/.local/lib/python3.8/site-packages/aiogram/bot/api.py", line 140, in make_request
    return check_result(method, response.content_type, response.status, await response.text())
  File "/home/danek/.local/lib/python3.8/site-packages/aiogram/bot/api.py", line 119, in check_result
    exceptions.ConflictError.detect(description)
  File "/home/danek/.local/lib/python3.8/site-packages/aiogram/utils/exceptions.py", line 140, in detect
    raise err(cls.text or description)
aiogram.utils.exceptions.TerminatedByOtherGetUpdates: Terminated by other getupdates request; make sure that only one bot instance is running
ERROR:aiogram.dispatcher.dispatcher:Cause exception while getting updates.
Traceback (most recent call last):
  File "/home/danek/.local/lib/python3.8/site-packages/aiogram/dispatcher/dispatcher.py", line 380, in start_polling
    updates = await self.bot.get_updates(
  File "/home/danek/.local/lib/python3.8/site-packages/aiogram/bot/bot.py", line 97, in get_updates
    result = await self.request(api.Methods.GET_UPDATES, payload)
  File "/home/danek/.local/lib/python3.8/site-packages/aiogram/bot/base.py", line 208, in request
    return await api.make_request(self.session, self.server, self.__token, method, data, files,
  File "/home/danek/.local/lib/python3.8/site-packages/aiogram/bot/api.py", line 140, in make_request
    return check_result(method, response.content_type, response.status, await response.text())
  File "/home/danek/.local/lib/python3.8/site-packages/aiogram/bot/api.py", line 119, in check_result
    exceptions.ConflictError.detect(description)
  File "/home/danek/.local/lib/python3.8/site-packages/aiogram/utils/exceptions.py", line 140, in detect
    raise err(cls.text or description)
aiogram.utils.exceptions.TerminatedByOtherGetUpdates: Terminated by other getupdates request; make sure that only one bot instance is running
ERROR:aiogram.dispatcher.dispatcher:Cause exception while getting updates.
Traceback (most recent call last):
  File "/home/danek/.local/lib/python3.8/site-packages/aiogram/dispatcher/dispatcher.py", line 380, in start_polling
    updates = await self.bot.get_updates(
  File "/home/danek/.local/lib/python3.8/site-packages/aiogram/bot/bot.py", line 97, in get_updates
    result = await self.request(api.Methods.GET_UPDATES, payload)
  File "/home/danek/.local/lib/python3.8/site-packages/aiogram/bot/base.py", line 208, in request
    return await api.make_request(self.session, self.server, self.__token, method, data, files,
  File "/home/danek/.local/lib/python3.8/site-packages/aiogram/bot/api.py", line 140, in make_request
    return check_result(method, response.content_type, response.status, await response.text())
  File "/home/danek/.local/lib/python3.8/site-packages/aiogram/bot/api.py", line 119, in check_result
    exceptions.ConflictError.detect(description)
  File "/home/danek/.local/lib/python3.8/site-packages/aiogram/utils/exceptions.py", line 140, in detect
    raise err(cls.text or description)
aiogram.utils.exceptions.TerminatedByOtherGetUpdates: Terminated by other getupdates request; make sure that only one bot instance is running
ERROR:aiogram.dispatcher.dispatcher:Cause exception while getting updates.
Traceback (most recent call last):
  File "/home/danek/.local/lib/python3.8/site-packages/aiogram/dispatcher/dispatcher.py", line 380, in start_polling
    updates = await self.bot.get_updates(
  File "/home/danek/.local/lib/python3.8/site-packages/aiogram/bot/bot.py", line 97, in get_updates
    result = await self.request(api.Methods.GET_UPDATES, payload)
  File "/home/danek/.local/lib/python3.8/site-packages/aiogram/bot/base.py", line 208, in request
    return await api.make_request(self.session, self.server, self.__token, method, data, files,
  File "/home/danek/.local/lib/python3.8/site-packages/aiogram/bot/api.py", line 140, in make_request
    return check_result(method, response.content_type, response.status, await response.text())
  File "/home/danek/.local/lib/python3.8/site-packages/aiogram/bot/api.py", line 119, in check_result
    exceptions.ConflictError.detect(description)
  File "/home/danek/.local/lib/python3.8/site-packages/aiogram/utils/exceptions.py", line 140, in detect
    raise err(cls.text or description)
aiogram.utils.exceptions.TerminatedByOtherGetUpdates: Terminated by other getupdates request; make sure that only one bot instance is running
ERROR:aiogram.dispatcher.dispatcher:Cause exception while getting updates.
Traceback (most recent call last):
  File "/home/danek/.local/lib/python3.8/site-packages/aiogram/dispatcher/dispatcher.py", line 380, in start_polling
    updates = await self.bot.get_updates(
  File "/home/danek/.local/lib/python3.8/site-packages/aiogram/bot/bot.py", line 97, in get_updates
    result = await self.request(api.Methods.GET_UPDATES, payload)
  File "/home/danek/.local/lib/python3.8/site-packages/aiogram/bot/base.py", line 208, in request
    return await api.make_request(self.session, self.server, self.__token, method, data, files,
  File "/home/danek/.local/lib/python3.8/site-packages/aiogram/bot/api.py", line 140, in make_request
    return check_result(method, response.content_type, response.status, await response.text())
  File "/home/danek/.local/lib/python3.8/site-packages/aiogram/bot/api.py", line 119, in check_result
    exceptions.ConflictError.detect(description)
  File "/home/danek/.local/lib/python3.8/site-packages/aiogram/utils/exceptions.py", line 140, in detect
    raise err(cls.text or description)
aiogram.utils.exceptions.TerminatedByOtherGetUpdates: Terminated by other getupdates request; make sure that only one bot instance is running
ERROR:aiogram.dispatcher.dispatcher:Cause exception while getting updates.
Traceback (most recent call last):
  File "/home/danek/.local/lib/python3.8/site-packages/aiogram/dispatcher/dispatcher.py", line 380, in start_polling
    updates = await self.bot.get_updates(
  File "/home/danek/.local/lib/python3.8/site-packages/aiogram/bot/bot.py", line 97, in get_updates
    result = await self.request(api.Methods.GET_UPDATES, payload)
  File "/home/danek/.local/lib/python3.8/site-packages/aiogram/bot/base.py", line 208, in request
    return await api.make_request(self.session, self.server, self.__token, method, data, files,
  File "/home/danek/.local/lib/python3.8/site-packages/aiogram/bot/api.py", line 140, in make_request
    return check_result(method, response.content_type, response.status, await response.text())
  File "/home/danek/.local/lib/python3.8/site-packages/aiogram/bot/api.py", line 119, in check_result
    exceptions.ConflictError.detect(description)
  File "/home/danek/.local/lib/python3.8/site-packages/aiogram/utils/exceptions.py", line 140, in detect
    raise err(cls.text or description)
aiogram.utils.exceptions.TerminatedByOtherGetUpdates: Terminated by other getupdates request; make sure that only one bot instance is running
ERROR:aiogram.dispatcher.dispatcher:Cause exception while getting updates.
Traceback (most recent call last):
  File "/home/danek/.local/lib/python3.8/site-packages/aiogram/dispatcher/dispatcher.py", line 380, in start_polling
    updates = await self.bot.get_updates(
  File "/home/danek/.local/lib/python3.8/site-packages/aiogram/bot/bot.py", line 97, in get_updates
    result = await self.request(api.Methods.GET_UPDATES, payload)
  File "/home/danek/.local/lib/python3.8/site-packages/aiogram/bot/base.py", line 208, in request
    return await api.make_request(self.session, self.server, self.__token, method, data, files,
  File "/home/danek/.local/lib/python3.8/site-packages/aiogram/bot/api.py", line 140, in make_request
    return check_result(method, response.content_type, response.status, await response.text())
  File "/home/danek/.local/lib/python3.8/site-packages/aiogram/bot/api.py", line 119, in check_result
    exceptions.ConflictError.detect(description)
  File "/home/danek/.local/lib/python3.8/site-packages/aiogram/utils/exceptions.py", line 140, in detect
    raise err(cls.text or description)
aiogram.utils.exceptions.TerminatedByOtherGetUpdates: Terminated by other getupdates request; make sure that only one bot instance is running
ERROR:aiogram.dispatcher.dispatcher:Cause exception while getting updates.
Traceback (most recent call last):
  File "/home/danek/.local/lib/python3.8/site-packages/aiogram/dispatcher/dispatcher.py", line 380, in start_polling
    updates = await self.bot.get_updates(
  File "/home/danek/.local/lib/python3.8/site-packages/aiogram/bot/bot.py", line 97, in get_updates
    result = await self.request(api.Methods.GET_UPDATES, payload)
  File "/home/danek/.local/lib/python3.8/site-packages/aiogram/bot/base.py", line 208, in request
    return await api.make_request(self.session, self.server, self.__token, method, data, files,
  File "/home/danek/.local/lib/python3.8/site-packages/aiogram/bot/api.py", line 140, in make_request
    return check_result(method, response.content_type, response.status, await response.text())
  File "/home/danek/.local/lib/python3.8/site-packages/aiogram/bot/api.py", line 119, in check_result
    exceptions.ConflictError.detect(description)
  File "/home/danek/.local/lib/python3.8/site-packages/aiogram/utils/exceptions.py", line 140, in detect
    raise err(cls.text or description)
aiogram.utils.exceptions.TerminatedByOtherGetUpdates: Terminated by other getupdates request; make sure that only one bot instance is running
ERROR:aiogram.dispatcher.dispatcher:Cause exception while getting updates.
Traceback (most recent call last):
  File "/home/danek/.local/lib/python3.8/site-packages/aiogram/dispatcher/dispatcher.py", line 380, in start_polling
    updates = await self.bot.get_updates(
  File "/home/danek/.local/lib/python3.8/site-packages/aiogram/bot/bot.py", line 97, in get_updates
    result = await self.request(api.Methods.GET_UPDATES, payload)
  File "/home/danek/.local/lib/python3.8/site-packages/aiogram/bot/base.py", line 208, in request
    return await api.make_request(self.session, self.server, self.__token, method, data, files,
  File "/home/danek/.local/lib/python3.8/site-packages/aiogram/bot/api.py", line 140, in make_request
    return check_result(method, response.content_type, response.status, await response.text())
  File "/home/danek/.local/lib/python3.8/site-packages/aiogram/bot/api.py", line 119, in check_result
    exceptions.ConflictError.detect(description)
  File "/home/danek/.local/lib/python3.8/site-packages/aiogram/utils/exceptions.py", line 140, in detect
    raise err(cls.text or description)
aiogram.utils.exceptions.TerminatedByOtherGetUpdates: Terminated by other getupdates request; make sure that only one bot instance is running
ERROR:aiogram.dispatcher.dispatcher:Cause exception while getting updates.
Traceback (most recent call last):
  File "/home/danek/.local/lib/python3.8/site-packages/aiogram/dispatcher/dispatcher.py", line 380, in start_polling
    updates = await self.bot.get_updates(
  File "/home/danek/.local/lib/python3.8/site-packages/aiogram/bot/bot.py", line 97, in get_updates
    result = await self.request(api.Methods.GET_UPDATES, payload)
  File "/home/danek/.local/lib/python3.8/site-packages/aiogram/bot/base.py", line 208, in request
    return await api.make_request(self.session, self.server, self.__token, method, data, files,
  File "/home/danek/.local/lib/python3.8/site-packages/aiogram/bot/api.py", line 140, in make_request
    return check_result(method, response.content_type, response.status, await response.text())
  File "/home/danek/.local/lib/python3.8/site-packages/aiogram/bot/api.py", line 119, in check_result
    exceptions.ConflictError.detect(description)
  File "/home/danek/.local/lib/python3.8/site-packages/aiogram/utils/exceptions.py", line 140, in detect
    raise err(cls.text or description)
aiogram.utils.exceptions.TerminatedByOtherGetUpdates: Terminated by other getupdates request; make sure that only one bot instance is running
ERROR:aiogram.dispatcher.dispatcher:Cause exception while getting updates.
Traceback (most recent call last):
  File "/home/danek/.local/lib/python3.8/site-packages/aiogram/dispatcher/dispatcher.py", line 380, in start_polling
    updates = await self.bot.get_updates(
  File "/home/danek/.local/lib/python3.8/site-packages/aiogram/bot/bot.py", line 97, in get_updates
    result = await self.request(api.Methods.GET_UPDATES, payload)
  File "/home/danek/.local/lib/python3.8/site-packages/aiogram/bot/base.py", line 208, in request
    return await api.make_request(self.session, self.server, self.__token, method, data, files,
  File "/home/danek/.local/lib/python3.8/site-packages/aiogram/bot/api.py", line 140, in make_request
    return check_result(method, response.content_type, response.status, await response.text())
  File "/home/danek/.local/lib/python3.8/site-packages/aiogram/bot/api.py", line 119, in check_result
    exceptions.ConflictError.detect(description)
  File "/home/danek/.local/lib/python3.8/site-packages/aiogram/utils/exceptions.py", line 140, in detect
    raise err(cls.text or description)
aiogram.utils.exceptions.TerminatedByOtherGetUpdates: Terminated by other getupdates request; make sure that only one bot instance is running
ERROR:aiogram.dispatcher.dispatcher:Cause exception while getting updates.
Traceback (most recent call last):
  File "/home/danek/.local/lib/python3.8/site-packages/aiogram/dispatcher/dispatcher.py", line 380, in start_polling
    updates = await self.bot.get_updates(
  File "/home/danek/.local/lib/python3.8/site-packages/aiogram/bot/bot.py", line 97, in get_updates
    result = await self.request(api.Methods.GET_UPDATES, payload)
  File "/home/danek/.local/lib/python3.8/site-packages/aiogram/bot/base.py", line 208, in request
    return await api.make_request(self.session, self.server, self.__token, method, data, files,
  File "/home/danek/.local/lib/python3.8/site-packages/aiogram/bot/api.py", line 140, in make_request
    return check_result(method, response.content_type, response.status, await response.text())
  File "/home/danek/.local/lib/python3.8/site-packages/aiogram/bot/api.py", line 119, in check_result
    exceptions.ConflictError.detect(description)
  File "/home/danek/.local/lib/python3.8/site-packages/aiogram/utils/exceptions.py", line 140, in detect
    raise err(cls.text or description)
aiogram.utils.exceptions.TerminatedByOtherGetUpdates: Terminated by other getupdates request; make sure that only one bot instance is running
ERROR:aiogram.dispatcher.dispatcher:Cause exception while getting updates.
Traceback (most recent call last):
  File "/home/danek/.local/lib/python3.8/site-packages/aiogram/dispatcher/dispatcher.py", line 380, in start_polling
    updates = await self.bot.get_updates(
  File "/home/danek/.local/lib/python3.8/site-packages/aiogram/bot/bot.py", line 97, in get_updates
    result = await self.request(api.Methods.GET_UPDATES, payload)
  File "/home/danek/.local/lib/python3.8/site-packages/aiogram/bot/base.py", line 208, in request
    return await api.make_request(self.session, self.server, self.__token, method, data, files,
  File "/home/danek/.local/lib/python3.8/site-packages/aiogram/bot/api.py", line 140, in make_request
    return check_result(method, response.content_type, response.status, await response.text())
  File "/home/danek/.local/lib/python3.8/site-packages/aiogram/bot/api.py", line 119, in check_result
    exceptions.ConflictError.detect(description)
  File "/home/danek/.local/lib/python3.8/site-packages/aiogram/utils/exceptions.py", line 140, in detect
    raise err(cls.text or description)
aiogram.utils.exceptions.TerminatedByOtherGetUpdates: Terminated by other getupdates request; make sure that only one bot instance is running
ERROR:aiogram.dispatcher.dispatcher:Cause exception while getting updates.
Traceback (most recent call last):
  File "/home/danek/.local/lib/python3.8/site-packages/aiogram/dispatcher/dispatcher.py", line 380, in start_polling
    updates = await self.bot.get_updates(
  File "/home/danek/.local/lib/python3.8/site-packages/aiogram/bot/bot.py", line 97, in get_updates
    result = await self.request(api.Methods.GET_UPDATES, payload)
  File "/home/danek/.local/lib/python3.8/site-packages/aiogram/bot/base.py", line 208, in request
    return await api.make_request(self.session, self.server, self.__token, method, data, files,
  File "/home/danek/.local/lib/python3.8/site-packages/aiogram/bot/api.py", line 140, in make_request
    return check_result(method, response.content_type, response.status, await response.text())
  File "/home/danek/.local/lib/python3.8/site-packages/aiogram/bot/api.py", line 119, in check_result
    exceptions.ConflictError.detect(description)
  File "/home/danek/.local/lib/python3.8/site-packages/aiogram/utils/exceptions.py", line 140, in detect
    raise err(cls.text or description)
aiogram.utils.exceptions.TerminatedByOtherGetUpdates: Terminated by other getupdates request; make sure that only one bot instance is running
ERROR:aiogram.dispatcher.dispatcher:Cause exception while getting updates.
Traceback (most recent call last):
  File "/home/danek/.local/lib/python3.8/site-packages/aiogram/dispatcher/dispatcher.py", line 380, in start_polling
    updates = await self.bot.get_updates(
  File "/home/danek/.local/lib/python3.8/site-packages/aiogram/bot/bot.py", line 97, in get_updates
    result = await self.request(api.Methods.GET_UPDATES, payload)
  File "/home/danek/.local/lib/python3.8/site-packages/aiogram/bot/base.py", line 208, in request
    return await api.make_request(self.session, self.server, self.__token, method, data, files,
  File "/home/danek/.local/lib/python3.8/site-packages/aiogram/bot/api.py", line 140, in make_request
    return check_result(method, response.content_type, response.status, await response.text())
  File "/home/danek/.local/lib/python3.8/site-packages/aiogram/bot/api.py", line 119, in check_result
    exceptions.ConflictError.detect(description)
  File "/home/danek/.local/lib/python3.8/site-packages/aiogram/utils/exceptions.py", line 140, in detect
    raise err(cls.text or description)
aiogram.utils.exceptions.TerminatedByOtherGetUpdates: Terminated by other getupdates request; make sure that only one bot instance is running
ERROR:aiogram.dispatcher.dispatcher:Cause exception while getting updates.
Traceback (most recent call last):
  File "/home/danek/.local/lib/python3.8/site-packages/aiogram/dispatcher/dispatcher.py", line 380, in start_polling
    updates = await self.bot.get_updates(
  File "/home/danek/.local/lib/python3.8/site-packages/aiogram/bot/bot.py", line 97, in get_updates
    result = await self.request(api.Methods.GET_UPDATES, payload)
  File "/home/danek/.local/lib/python3.8/site-packages/aiogram/bot/base.py", line 208, in request
    return await api.make_request(self.session, self.server, self.__token, method, data, files,
  File "/home/danek/.local/lib/python3.8/site-packages/aiogram/bot/api.py", line 140, in make_request
    return check_result(method, response.content_type, response.status, await response.text())
  File "/home/danek/.local/lib/python3.8/site-packages/aiogram/bot/api.py", line 119, in check_result
    exceptions.ConflictError.detect(description)
  File "/home/danek/.local/lib/python3.8/site-packages/aiogram/utils/exceptions.py", line 140, in detect
    raise err(cls.text or description)
aiogram.utils.exceptions.TerminatedByOtherGetUpdates: Terminated by other getupdates request; make sure that only one bot instance is running
ERROR:aiogram.dispatcher.dispatcher:Cause exception while getting updates.
Traceback (most recent call last):
  File "/home/danek/.local/lib/python3.8/site-packages/aiogram/dispatcher/dispatcher.py", line 380, in start_polling
    updates = await self.bot.get_updates(
  File "/home/danek/.local/lib/python3.8/site-packages/aiogram/bot/bot.py", line 97, in get_updates
    result = await self.request(api.Methods.GET_UPDATES, payload)
  File "/home/danek/.local/lib/python3.8/site-packages/aiogram/bot/base.py", line 208, in request
    return await api.make_request(self.session, self.server, self.__token, method, data, files,
  File "/home/danek/.local/lib/python3.8/site-packages/aiogram/bot/api.py", line 140, in make_request
    return check_result(method, response.content_type, response.status, await response.text())
  File "/home/danek/.local/lib/python3.8/site-packages/aiogram/bot/api.py", line 119, in check_result
    exceptions.ConflictError.detect(description)
  File "/home/danek/.local/lib/python3.8/site-packages/aiogram/utils/exceptions.py", line 140, in detect
    raise err(cls.text or description)
aiogram.utils.exceptions.TerminatedByOtherGetUpdates: Terminated by other getupdates request; make sure that only one bot instance is running
INFO:root:Cancelling state Form:feedback
ERROR:asyncio:Task exception was never retrieved
future: <Task finished name='Task-117' coro=<Dispatcher._process_polling_updates() done, defined at /home/danek/.local/lib/python3.8/site-packages/aiogram/dispatcher/dispatcher.py:406> exception=TypeError('cancel() takes 0 positional arguments but 1 was given')>
Traceback (most recent call last):
  File "/home/danek/.local/lib/python3.8/site-packages/aiogram/dispatcher/dispatcher.py", line 414, in _process_polling_updates
    for responses in itertools.chain.from_iterable(await self.process_updates(updates, fast)):
  File "/home/danek/.local/lib/python3.8/site-packages/aiogram/dispatcher/dispatcher.py", line 236, in process_updates
    return await asyncio.gather(*tasks)
  File "/home/danek/.local/lib/python3.8/site-packages/aiogram/dispatcher/handler.py", line 116, in notify
    response = await handler_obj.handler(*args, **partial_data)
  File "/home/danek/.local/lib/python3.8/site-packages/aiogram/dispatcher/dispatcher.py", line 257, in process_update
    return await self.message_handlers.notify(update.message)
  File "/home/danek/.local/lib/python3.8/site-packages/aiogram/dispatcher/handler.py", line 116, in notify
    response = await handler_obj.handler(*args, **partial_data)
  File "/home/danek/here-i-ambot/handlers.py", line 65, in cancel_handler
    await cancel(message.from_user.id)
TypeError: cancel() takes 0 positional arguments but 1 was given
INFO:aiogram.dispatcher.dispatcher:Stop polling...
WARNING:aiogram:Goodbye!
INFO:aiogram:Bot: HereIAm [@here_i_ambot]
WARNING:aiogram:Updates were skipped successfully.
INFO:aiogram.dispatcher.dispatcher:Start polling.
INFO:aiogram.dispatcher.dispatcher:Stop polling...
WARNING:aiogram:Goodbye!
INFO:aiogram:Bot: HereIAm [@here_i_ambot]
WARNING:aiogram:Updates were skipped successfully.
INFO:aiogram.dispatcher.dispatcher:Start polling.
ERROR:asyncio:Task exception was never retrieved
future: <Task finished name='Task-203' coro=<Dispatcher._process_polling_updates() done, defined at /home/danek/.local/lib/python3.8/site-packages/aiogram/dispatcher/dispatcher.py:406> exception=IndexError('list index out of range')>
Traceback (most recent call last):
  File "/home/danek/.local/lib/python3.8/site-packages/aiogram/dispatcher/dispatcher.py", line 414, in _process_polling_updates
    for responses in itertools.chain.from_iterable(await self.process_updates(updates, fast)):
  File "/home/danek/.local/lib/python3.8/site-packages/aiogram/dispatcher/dispatcher.py", line 236, in process_updates
    return await asyncio.gather(*tasks)
  File "/home/danek/.local/lib/python3.8/site-packages/aiogram/dispatcher/handler.py", line 116, in notify
    response = await handler_obj.handler(*args, **partial_data)
  File "/home/danek/.local/lib/python3.8/site-packages/aiogram/dispatcher/dispatcher.py", line 257, in process_update
    return await self.message_handlers.notify(update.message)
  File "/home/danek/.local/lib/python3.8/site-packages/aiogram/dispatcher/handler.py", line 116, in notify
    response = await handler_obj.handler(*args, **partial_data)
  File "/home/danek/here-i-ambot/handlers.py", line 160, in give_contact
    await bot.send_message(chat_id=queries[message.from_user.id][-1],
IndexError: list index out of range
ERROR:asyncio:Task exception was never retrieved
future: <Task finished name='Task-206' coro=<Dispatcher._process_polling_updates() done, defined at /home/danek/.local/lib/python3.8/site-packages/aiogram/dispatcher/dispatcher.py:406> exception=IndexError('list index out of range')>
Traceback (most recent call last):
  File "/home/danek/.local/lib/python3.8/site-packages/aiogram/dispatcher/dispatcher.py", line 414, in _process_polling_updates
    for responses in itertools.chain.from_iterable(await self.process_updates(updates, fast)):
  File "/home/danek/.local/lib/python3.8/site-packages/aiogram/dispatcher/dispatcher.py", line 236, in process_updates
    return await asyncio.gather(*tasks)
  File "/home/danek/.local/lib/python3.8/site-packages/aiogram/dispatcher/handler.py", line 116, in notify
    response = await handler_obj.handler(*args, **partial_data)
  File "/home/danek/.local/lib/python3.8/site-packages/aiogram/dispatcher/dispatcher.py", line 257, in process_update
    return await self.message_handlers.notify(update.message)
  File "/home/danek/.local/lib/python3.8/site-packages/aiogram/dispatcher/handler.py", line 116, in notify
    response = await handler_obj.handler(*args, **partial_data)
  File "/home/danek/here-i-ambot/handlers.py", line 160, in give_contact
    await bot.send_message(chat_id=queries[message.from_user.id][-1],
IndexError: list index out of range
ERROR:asyncio:Task exception was never retrieved
future: <Task finished name='Task-323' coro=<Dispatcher._process_polling_updates() done, defined at /home/danek/.local/lib/python3.8/site-packages/aiogram/dispatcher/dispatcher.py:406> exception=IndexError('list index out of range')>
Traceback (most recent call last):
  File "/home/danek/.local/lib/python3.8/site-packages/aiogram/dispatcher/dispatcher.py", line 414, in _process_polling_updates
    for responses in itertools.chain.from_iterable(await self.process_updates(updates, fast)):
  File "/home/danek/.local/lib/python3.8/site-packages/aiogram/dispatcher/dispatcher.py", line 236, in process_updates
    return await asyncio.gather(*tasks)
  File "/home/danek/.local/lib/python3.8/site-packages/aiogram/dispatcher/handler.py", line 116, in notify
    response = await handler_obj.handler(*args, **partial_data)
  File "/home/danek/.local/lib/python3.8/site-packages/aiogram/dispatcher/dispatcher.py", line 257, in process_update
    return await self.message_handlers.notify(update.message)
  File "/home/danek/.local/lib/python3.8/site-packages/aiogram/dispatcher/handler.py", line 116, in notify
    response = await handler_obj.handler(*args, **partial_data)
  File "/home/danek/here-i-ambot/handlers.py", line 160, in give_contact
    await bot.send_message(chat_id=queries[message.from_user.id][-1],
IndexError: list index out of range
ERROR:asyncio:Task exception was never retrieved
future: <Task finished name='Task-330' coro=<Dispatcher._process_polling_updates() done, defined at /home/danek/.local/lib/python3.8/site-packages/aiogram/dispatcher/dispatcher.py:406> exception=IndexError('list index out of range')>
Traceback (most recent call last):
  File "/home/danek/.local/lib/python3.8/site-packages/aiogram/dispatcher/dispatcher.py", line 414, in _process_polling_updates
    for responses in itertools.chain.from_iterable(await self.process_updates(updates, fast)):
  File "/home/danek/.local/lib/python3.8/site-packages/aiogram/dispatcher/dispatcher.py", line 236, in process_updates
    return await asyncio.gather(*tasks)
  File "/home/danek/.local/lib/python3.8/site-packages/aiogram/dispatcher/handler.py", line 116, in notify
    response = await handler_obj.handler(*args, **partial_data)
  File "/home/danek/.local/lib/python3.8/site-packages/aiogram/dispatcher/dispatcher.py", line 257, in process_update
    return await self.message_handlers.notify(update.message)
  File "/home/danek/.local/lib/python3.8/site-packages/aiogram/dispatcher/handler.py", line 116, in notify
    response = await handler_obj.handler(*args, **partial_data)
  File "/home/danek/here-i-ambot/handlers.py", line 160, in give_contact
    await bot.send_message(chat_id=queries[message.from_user.id][-1],
IndexError: list index out of range
ERROR:asyncio:Task exception was never retrieved
future: <Task finished name='Task-384' coro=<Dispatcher._process_polling_updates() done, defined at /home/danek/.local/lib/python3.8/site-packages/aiogram/dispatcher/dispatcher.py:406> exception=IndexError('list index out of range')>
Traceback (most recent call last):
  File "/home/danek/.local/lib/python3.8/site-packages/aiogram/dispatcher/dispatcher.py", line 414, in _process_polling_updates
    for responses in itertools.chain.from_iterable(await self.process_updates(updates, fast)):
  File "/home/danek/.local/lib/python3.8/site-packages/aiogram/dispatcher/dispatcher.py", line 236, in process_updates
    return await asyncio.gather(*tasks)
  File "/home/danek/.local/lib/python3.8/site-packages/aiogram/dispatcher/handler.py", line 116, in notify
    response = await handler_obj.handler(*args, **partial_data)
  File "/home/danek/.local/lib/python3.8/site-packages/aiogram/dispatcher/dispatcher.py", line 257, in process_update
    return await self.message_handlers.notify(update.message)
  File "/home/danek/.local/lib/python3.8/site-packages/aiogram/dispatcher/handler.py", line 116, in notify
    response = await handler_obj.handler(*args, **partial_data)
  File "/home/danek/here-i-ambot/handlers.py", line 160, in give_contact
    await bot.send_message(chat_id=queries[message.from_user.id][-1],
IndexError: list index out of range
ERROR:asyncio:Task exception was never retrieved
future: <Task finished name='Task-402' coro=<Dispatcher._process_polling_updates() done, defined at /home/danek/.local/lib/python3.8/site-packages/aiogram/dispatcher/dispatcher.py:406> exception=IndexError('list index out of range')>
Traceback (most recent call last):
  File "/home/danek/.local/lib/python3.8/site-packages/aiogram/dispatcher/dispatcher.py", line 414, in _process_polling_updates
    for responses in itertools.chain.from_iterable(await self.process_updates(updates, fast)):
  File "/home/danek/.local/lib/python3.8/site-packages/aiogram/dispatcher/dispatcher.py", line 236, in process_updates
    return await asyncio.gather(*tasks)
  File "/home/danek/.local/lib/python3.8/site-packages/aiogram/dispatcher/handler.py", line 116, in notify
    response = await handler_obj.handler(*args, **partial_data)
  File "/home/danek/.local/lib/python3.8/site-packages/aiogram/dispatcher/dispatcher.py", line 257, in process_update
    return await self.message_handlers.notify(update.message)
  File "/home/danek/.local/lib/python3.8/site-packages/aiogram/dispatcher/handler.py", line 116, in notify
    response = await handler_obj.handler(*args, **partial_data)
  File "/home/danek/here-i-ambot/handlers.py", line 160, in give_contact
    await bot.send_message(chat_id=queries[message.from_user.id][-1],
IndexError: list index out of range
INFO:aiogram.dispatcher.dispatcher:Stop polling...
WARNING:aiogram:Goodbye!
INFO:aiogram:Bot: HereIAm [@here_i_ambot]
WARNING:aiogram:Updates were skipped successfully.
INFO:aiogram.dispatcher.dispatcher:Start polling.
INFO:aiogram.dispatcher.dispatcher:Stop polling...
WARNING:aiogram:Goodbye!
INFO:aiogram:Bot: HereIAm [@here_i_ambot]
WARNING:aiogram:Updates were skipped successfully.
INFO:aiogram.dispatcher.dispatcher:Start polling.
INFO:aiogram.dispatcher.dispatcher:Stop polling...
WARNING:aiogram:Goodbye!
